Workbook

Sheet Historical VaR
A1: Historical VaR Calculation (Historical Simulation Method)
A2: Student: | B2: Advait Srivastava | D2: ID: | E2: 2022A4PS1181H | G2: Theme: | H2: Risk Management | J2: Data Source: | K2: S&P Capital IQ (WILP Finance Lab)
A3: Data Retrieved: | B3: June 13, 2026 | D3: Period: | E3: Jun 13, 2025 - Jun 11, 2026
A5: Portfolio Weights | F5: Base Prices (for CIQ % reconstruction) | I5: Historical Simulation VaR | L5: Variance-Covariance VaR
B6: Stock Name | C6: Amount (INR) | D6: Weight | F6: Stock | G6: Base Price (INR) | H6: Note | I6: Metric | J6: Value | L6: Metric | M6: Value
A7: Asset 1 | B7: TCS | C7: 100000 | D7: =C7/C12 -> 0.2 | F7: TCS | G7: 3666.82 | H7: CIQ base (0%) anchor | I7: 95% VaR (1-day, %) | J7: =PERCENTILE(O19:O262,0.05) -> -0.023367821 | L7: Portfolio Std Dev | M7: =STDEV(O19:O262) -> 0.011115474
A8: Asset 2 | B8: Wipro | C8: 100000 | D8: =C8/C12 -> 0.2 | F8: Wipro | G8: 243.65 | H8: CIQ base (0%) anchor | I8: 95% VaR (INR) | J8: =ABS(J7)*C12 -> 11683.91 | L8: 95% VaR (%) [z=1.645] | M8: =1.645*M7 -> 0.018284955
A9: Asset 3 | B9: Bharti Airtel | C9: 100000 | D9: =C9/C12 -> 0.2 | F9: Bharti Airtel | G9: 1839.66 | H9: CIQ base (0%) anchor | I9: 99% VaR (1-day, %) | J9: =PERCENTILE(O19:O262,0.01) -> -0.029295334 | L9: 95% VaR (INR) | M9: =M8*C12 -> 9142.4776
A10: Asset 4 | B10: Adani Ent | C10: 100000 | D10: =C10/C12 -> 0.2 | F10: Adani Ent | G10: 2613.83 | H10: CIQ base (0%) anchor | I10: 99% VaR (INR) | J10: =ABS(J9)*C12 -> 14647.667 | L10: 99% VaR (%) [z=2.33] | M10: =2.33*M7 -> 0.025899055
A11: Asset 5 | B11: Godrej Ind | C11: 100000 | D11: =C11/C12 -> 0.2 | F11: Godrej Ind | G11: 1320.57 | H11: CIQ base (0%) anchor | I11: 95% VaR (10-day, INR) | J11: =J8*SQRT(10) -> 36947.769 | L11: 99% VaR (INR) | M11: =M10*C12 -> 12949.528
A12: Total | C12: =SUM(C7:C11) -> 500000 | D12: =SUM(D7:D11) -> 1 | F12: Price formula: | G12: BasePrice * (1 + CIQ%/100) | I12: 99% VaR (10-day, INR) | J12: =J10*SQRT(10) -> 46319.989 | L12: 95% VaR (10-day, INR) | M12: =M9*SQRT(10) -> 28911.053
A14: Closing prices reconstructed from S&P Capital IQ cumulative % data: Price = Base Price * (1 + CIQ_Percentage / 100). Log returns = LN(Pt/Pt-1).
C16: Closing Prices (INR) [from CIQ %] | I16: Log Returns | O16: Portfolio
A17: # | B17: Date | C17: TCS | D17: Wipro | E17: Bharti Airtel | F17: Adani Ent | G17: Godrej Ind | I17: TCS | J17: Wipro | K17: Bharti Airtel | L17: Adani Ent | M17: Godrej Ind | O17: Wtd Return
A18: 1 | B18: 45821 | C18: =$G$7*(1+INDEX(TCS!$B:$B,MATCH($B18,TCS!$A:$A,0))/100) -> 3315.2533 | D18: =$G$8*(1+INDEX(Wipro!$B:$B,MATCH($B18,Wipro!$A:$A,0))/100) -> 248.76488 | E18: =$G$9*(1+INDEX('Bharti Airtel'!$B:$B,MATCH($B18,'Bharti Airtel'!$A:$A,0))/100) -> 1825.1452 | F18: =$G$10*(1+INDEX('Adani Enterprises'!$B:$B,MATCH($B18,'Adani Enterprises'!$A:$A,0))/100) -> 2506.7747 | G18: =$G$11*(1+INDEX(Godrej!$B:$B,MATCH($B18,Godrej!$A:$A,0))/100) -> 1278.1031
A19: 2 | B19: 45824 | C19: =$G$7*(1+INDEX(TCS!$B:$B,MATCH($B19,TCS!$A:$A,0))/100) -> 3363.9376 | D19: =$G$8*(1+INDEX(Wipro!$B:$B,MATCH($B19,Wipro!$A:$A,0))/100) -> 251.39403 | E19: =$G$9*(1+INDEX('Bharti Airtel'!$B:$B,MATCH($B19,'Bharti Airtel'!$A:$A,0))/100) -> 1844.1185 | F19: =$G$10*(1+INDEX('Adani Enterprises'!$B:$B,MATCH($B19,'Adani Enterprises'!$A:$A,0))/100) -> 2547.0767 | G19: =$G$11*(1+INDEX(Godrej!$B:$B,MATCH($B19,Godrej!$A:$A,0))/100) -> 1302.0345 | I19: =LN(C19/C18) -> 0.01457819 | J19: =LN(D19/D18) -> 0.010513334 | K19: =LN(E19/E18) -> 0.010341801 | L19: =LN(F19/F18) -> 0.015949365 | M19: =LN(G19/G18) -> 0.018550965 | O19: =$D$7*I19+$D$8*J19+$D$9*K19+$D$10*L19+$D$11*M19 -> 0.013986731
A20: 3 | B20: 45825 | C20: =$G$7*(1+INDEX(TCS!$B:$B,MATCH($B20,TCS!$A:$A,0))/100) -> 3382.2183 | D20: =$G$8*(1+INDEX(Wipro!$B:$B,MATCH($B20,Wipro!$A:$A,0))/100) -> 251.29842 | E20: =$G$9*(1+INDEX('Bharti Airtel'!$B:$B,MATCH($B20,'Bharti Airtel'!$A:$A,0))/100) -> 1838.0748 | F20: =$G$10*(1+INDEX('Adani Enterprises'!$B:$B,MATCH($B20,'Adani Enterprises'!$A:$A,0))/100) -> 2488.0237 | G20: =$G$11*(1+INDEX(Godrej!$B:$B,MATCH($B20,Godrej!$A:$A,0))/100) -> 1318.1219 | I20: =LN(C20/C19) -> 0.0054196037 | J20: =LN(D20/D19) -> -0.00038037277 | K20: =LN(E20/E19) -> -0.0032826614 | L20: =LN(F20/F19) -> -0.023457584 | M20: =LN(G20/G19) -> 0.012279919 | O20: =$D$7*I20+$D$8*J20+$D$9*K20+$D$10*L20+$D$11*M20 -> -0.001884219
A21: 4 | B21: 45826 | C21: =$G$7*(1+INDEX(TCS!$B:$B,MATCH($B21,TCS!$A:$A,0))/100) -> 3320.7375 | D21: =$G$8*(1+INDEX(Wipro!$B:$B,MATCH($B21,Wipro!$A:$A,0))/100) -> 250.05555 | E21: =$G$9*(1+INDEX('Bharti Airtel'!$B:$B,MATCH($B21,'Bharti Airtel'!$A:$A,0))/100) -> 1847.9329 | F21: =$G$10*(1+INDEX('Adani Enterprises'!$B:$B,MATCH($B21,'Adani Enterprises'!$A:$A,0))/100) -> 2458.4223 | G21: =$G$11*(1+INDEX(Godrej!$B:$B,MATCH($B21,Godrej!$A:$A,0))/100) -> 1345.9502 | I21: =LN(C21/C20) -> -0.018344924 | J21: =LN(D21/D20) -> -0.0049580574 | K21: =LN(E21/E20) -> 0.0053489719 | L21: =LN(F21/F20) -> -0.011968927 | M21: =LN(G21/G20) -> 0.020892308 | O21: =$D$7*I21+$D$8*J21+$D$9*K21+$D$10*L21+$D$11*M21 -> -0.0018061258
A22: 5 | B22: 45827 | C22: =$G$7*(1+INDEX(TCS!$B:$B,MATCH($B22,TCS!$A:$A,0))/100) -> 3294.3748 | D22: =$G$8*(1+INDEX(Wipro!$B:$B,MATCH($B22,Wipro!$A:$A,0))/100) -> 253.83196 | E22: =$G$9*(1+INDEX('Bharti Airtel'!$B:$B,MATCH($B22,'Bharti Airtel'!$A:$A,0))/100) -> 1858.2865 | F22: =$G$10*(1+INDEX('Adani Enterprises'!$B:$B,MATCH($B22,'Adani Enterprises'!$A:$A,0))/100) -> 2419.3203 | G22: =$G$11*(1+INDEX(Godrej!$B:$B,MATCH($B22,Godrej!$A:$A,0))/100) -> 1337.5068 | I22: =LN(C22/C21) -> -0.0079704876 | J22: =LN(D22/D21) -> 0.014989371 | K22: =LN(E22/E21) -> 0.0055871294 | L22: =LN(F22/F21) -> -0.016033147 | M22: =LN(G22/G21) -> -0.0062929589 | O22: =$D$7*I22+$D$8*J22+$D$9*K22+$D$10*L22+$D$11*M22 -> -0.0019440187
A23: 6 | B23: 45828 | C23: =$G$7*(1+INDEX(TCS!$B:$B,MATCH($B23,TCS!$A:$A,0))/100) -> 3305.6318 | D23: =$G$8*(1+INDEX(Wipro!$B:$B,MATCH($B23,Wipro!$A:$A,0))/100) -> 254.6446 | E23: =$G$9*(1+INDEX('Bharti Airtel'!$B:$B,MATCH($B23,'Bharti Airtel'!$A:$A,0))/100) -> 1919.0701 | F23: =$G$10*(1+INDEX('Adani Enterprises'!$B:$B,MATCH($B23,'Adani Enterprises'!$A:$A,0))/100) -> 2449.2218 | G23: =$G$11*(1+INDEX(Godrej!$B:$B,MATCH($B23,Godrej!$A:$A,0))/100) -> 1347.3991 | I23: =LN(C23/C22) -> 0.0034112312 | J23: =LN(D23/D22) -> 0.0031963927 | K23: =LN(E23/E22) -> 0.032185963 | L23: =LN(F23/F22) -> 0.012283703 | M23: =LN(G23/G22) -> 0.0073688461 | O23: =$D$7*I23+$D$8*J23+$D$9*K23+$D$10*L23+$D$11*M23 -> 0.011689227
A24: 7 | B24: 45831 | C24: =$G$7*(1+INDEX(TCS!$B:$B,MATCH($B24,TCS!$A:$A,0))/100) -> 3265.1256 | D24: =$G$8*(1+INDEX(Wipro!$B:$B,MATCH($B24,Wipro!$A:$A,0))/100) -> 251.53743 | E24: =$G$9*(1+INDEX('Bharti Airtel'!$B:$B,MATCH($B24,'Bharti Airtel'!$A:$A,0))/100) -> 1918.1784 | F24: =$G$10*(1+INDEX('Adani Enterprises'!$B:$B,MATCH($B24,'Adani Enterprises'!$A:$A,0))/100) -> 2471.5229 | G24: =$G$11*(1+INDEX(Godrej!$B:$B,MATCH($B24,Godrej!$A:$A,0))/100) -> 1281.6004 | I24: =LN(C24/C23) -> -0.012329385 | J24: =LN(D24/D23) -> -0.012277045 | K24: =LN(E24/E23) -> -0.00046475601 | L24: =LN(F24/F23) -> 0.0090641816 | M24: =LN(G24/G23) -> -0.050066517 | O24: =$D$7*I24+$D$8*J24+$D$9*K24+$D$10*L24+$D$11*M24 -> -0.013214704
A25: 8 | B25: 45832 | C25: =$G$7*(1+INDEX(TCS!$B:$B,MATCH($B25,TCS!$A:$A,0))/100) -> 3262.0468 | D25: =$G$8*(1+INDEX(Wipro!$B:$B,MATCH($B25,Wipro!$A:$A,0))/100) -> 253.30613 | E25: =$G$9*(1+INDEX('Bharti Airtel'!$B:$B,MATCH($B25,'Bharti Airtel'!$A:$A,0))/100) -> 1914.9584 | F25: =$G$10*(1+INDEX('Adani Enterprises'!$B:$B,MATCH($B25,'Adani Enterprises'!$A:$A,0))/100) -> 2507.0747 | G25: =$G$11*(1+INDEX(Godrej!$B:$B,MATCH($B25,Godrej!$A:$A,0))/100) -> 1252.3232 | I25: =LN(C25/C24) -> -0.0009433963 | J25: =LN(D25/D24) -> 0.0070069409 | K25: =LN(E25/E24) -> -0.0016800862 | L25: =LN(F25/F24) -> 0.014282083 | M25: =LN(G25/G24) -> -0.023109195 | O25: =$D$7*I25+$D$8*J25+$D$9*K25+$D$10*L25+$D$11*M25 -> -0.00088873072
A26: 9 | B26: 45833 | C26: =$G$7*(1+INDEX(TCS!$B:$B,MATCH($B26,TCS!$A:$A,0))/100) -> 3314.3873 | D26: =$G$8*(1+INDEX(Wipro!$B:$B,MATCH($B26,Wipro!$A:$A,0))/100) -> 257.56057 | E26: =$G$9*(1+INDEX('Bharti Airtel'!$B:$B,MATCH($B26,'Bharti Airtel'!$A:$A,0))/100) -> 1947.4061 | F26: =$G$10*(1+INDEX('Adani Enterprises'!$B:$B,MATCH($B26,'Adani Enterprises'!$A:$A,0))/100) -> 2527.0257 | G26: =$G$11*(1+INDEX(Godrej!$B:$B,MATCH($B26,Godrej!$A:$A,0))/100) -> 1247.3271 | I26: =LN(C26/C25) -> 0.015917939 | J26: =LN(D26/D25) -> 0.016656135 | K26: =LN(E26/E25) -> 0.016802376 | L26: =LN(F26/F25) -> 0.0079263802 | M26: =LN(G26/G25) -> -0.003997447 | O26: =$D$7*I26+$D$8*J26+$D$9*K26+$D$10*L26+$D$11*M26 -> 0.010661077
A27: 10 | B27: 45834 | C27: =$G$7*(1+INDEX(TCS!$B:$B,MATCH($B27,TCS!$A:$A,0))/100) -> 3311.5009 | D27: =$G$8*(1+INDEX(Wipro!$B:$B,MATCH($B27,Wipro!$A:$A,0))/100) -> 256.55671 | E27: =$G$9*(1+INDEX('Bharti Airtel'!$B:$B,MATCH($B27,'Bharti Airtel'!$A:$A,0))/100) -> 1995.6071 | F27: =$G$10*(1+INDEX('Adani Enterprises'!$B:$B,MATCH($B27,'Adani Enterprises'!$A:$A,0))/100) -> 2586.1286 | G27: =$G$11*(1+INDEX(Godrej!$B:$B,MATCH($B27,Godrej!$A:$A,0))/100) -> 1247.2772 | I27: =LN(C27/C26) -> -0.00087125728 | J27: =LN(D27/D26) -> -0.0039051654 | K27: =LN(E27/E26) -> 0.02444999 | L27: =LN(F27/F26) -> 0.023119025 | M27: =LN(G27/G26) -> -4.0055276e-05 | O27: =$D$7*I27+$D$8*J27+$D$9*K27+$D$10*L27+$D$11*M27 -> 0.0085505075
A28: 11 | B28: 45835 | C28: =$G$7*(1+INDEX(TCS!$B:$B,MATCH($B28,TCS!$A:$A,0))/100) -> 3310.8274 | D28: =$G$8*(1+INDEX(Wipro!$B:$B,MATCH($B28,Wipro!$A:$A,0))/100) -> 253.40174 | E28: =$G$9*(1+INDEX('Bharti Airtel'!$B:$B,MATCH($B28,'Bharti Airtel'!$A:$A,0))/100) -> 2009.1806 | F28: =$G$10*(1+INDEX('Adani Enterprises'!$B:$B,MATCH($B28,'Adani Enterprises'!$A:$A,0))/100) -> 2648.4817 | G28: =$G$11*(1+INDEX(Godrej!$B:$B,MATCH($B28,Godrej!$A:$A,0))/100) -> 1247.427 | I28: =LN(C28/C27) -> -0.00020340264 | J28: =LN(D28/D27) -> -0.012373611 | K28: =LN(E28/E27) -> 0.0067786806 | L28: =LN(F28/F27) -> 0.023824524 | M28: =LN(G28/G27) -> 0.00012016102 | O28: =$D$7*I28+$D$8*J28+$D$9*K28+$D$10*L28+$D$11*M28 -> 0.0036292704
A29: 12 | B29: 45838 | C29: =$G$7*(1+INDEX(TCS!$B:$B,MATCH($B29,TCS!$A:$A,0))/100) -> 3330.9362 | D29: =$G$8*(1+INDEX(Wipro!$B:$B,MATCH($B29,Wipro!$A:$A,0))/100) -> 254.30999 | E29: =$G$9*(1+INDEX('Bharti Airtel'!$B:$B,MATCH($B29,'Bharti Airtel'!$A:$A,0))/100) -> 1990.8514 | F29: =$G$10*(1+INDEX('Adani Enterprises'!$B:$B,MATCH($B29,'Adani Enterprises'!$A:$A,0))/100) -> 2618.9303 | G29: =$G$11*(1+INDEX(Godrej!$B:$B,MATCH($B29,Godrej!$A:$A,0))/100) -> 1246.228 | I29: =LN(C29/C28) -> 0.006055269 | J29: =LN(D29/D28) -> 0.0035778213 | K29: =LN(E29/E28) -> -0.0091646048 | L29: =LN(F29/F28) -> -0.011220607 | M29: =LN(G29/G28) -> -0.00096169265 | O29: =$D$7*I29+$D$8*J29+$D$9*K29+$D$10*L29+$D$11*M29 -> -0.0023427628
A30: 13 | B30: 45839 | C30: =$G$7*(1+INDEX(TCS!$B:$B,MATCH($B30,TCS!$A:$A,0))/100) -> 3299.859 | D30: =$G$8*(1+INDEX(Wipro!$B:$B,MATCH($B30,Wipro!$A:$A,0))/100) -> 252.8281 | E30: =$G$9*(1+INDEX('Bharti Airtel'!$B:$B,MATCH($B30,'Bharti Airtel'!$A:$A,0))/100) -> 2000.6104 | F30: =$G$10*(1+INDEX('Adani Enterprises'!$B:$B,MATCH($B30,'Adani Enterprises'!$A:$A,0))/100) -> 2620.3303 | G30: =$G$11*(1+INDEX(Godrej!$B:$B,MATCH($B30,Godrej!$A:$A,0))/100) -> 1206.7088 | I30: =LN(C30/C29) -> -0.009373663 | J30: =LN(D30/D29) -> -0.0058441113 | K30: =LN(E30/E29) -> 0.0048899853 | L30: =LN(F30/F29) -> 0.00053445315 | M30: =LN(G30/G29) -> -0.032224716 | O30: =$D$7*I30+$D$8*J30+$D$9*K30+$D$10*L30+$D$11*M30 -> -0.0084036104
... A262: 245 | B262: 46183 | C262: =$G$7*(1+INDEX(TCS!$B:$B,MATCH($B262,TCS!$A:$A,0))/100) -> 2072.358 | D262: =$G$8*(1+INDEX(Wipro!$B:$B,MATCH($B262,Wipro!$A:$A,0))/100) -> 171.08561 | E262: =$G$9*(1+INDEX('Bharti Airtel'!$B:$B,MATCH($B262,'Bharti Airtel'!$A:$A,0))/100) -> 1759.0114 | F262: =$G$10*(1+INDEX('Adani Enterprises'!$B:$B,MATCH($B262,'Adani Enterprises'!$A:$A,0))/100) -> 2930.1957 | G262: =$G$11*(1+INDEX(Godrej!$B:$B,MATCH($B262,Godrej!$A:$A,0))/100) -> 1036.2917 | I262: =LN(C262/C261) -> 0.0013473021 | J262: =LN(D262/D261) -> -0.015525679 | K262: =LN(E262/E261) -> -0.012593567 | L262: =LN(F262/F261) -> -0.016316392 | M262: =LN(G262/G261) -> -0.007157814 | O262: =$D$7*I262+$D$8*J262+$D$9*K262+$D$10*L262+$D$11*M262 -> -0.01004923

Sheet TCS
A2: Tata Consultancy Services Limited | Stock Chart
A4: NSEI:TCS (MI Key: 4092830; SPCIQ Key: 6411769)
A7: Entities: Tata Consultancy Services Ltd., S&P Asia Pacific Emerging BMI Information Technology (Sector) Index
A8: Metrics: Share Price, High Price, Low Price, Day Open Price, Volume
A45: SERIES NAME | B45: CATEGORY | C45: HIGH | D45: LOW | E45: AVERAGE | F45: CHANGE
A46: TCS-Share Price (Daily) | B46: Market Data | C46: 4,553.75 | D46: 2,151.00 | E46: 3,544.38 | F46: -1,639.50 | -43.22%
A47: S&P Asia Pacific Emerging BMI Information Technology (Sector) Index-Index Value (Daily) | B47: Market Data | C47: 657.19 | D47: 217.30 | E47: 338.02 | F47: 369.42 | 159.54%
A48: TCS-High Price (Daily) | B48: Market Data | C48: 4,592.25 | D48: 2,177.00 | E48: 3,596.56 | F48: -1,651.20 | -43.09%
A49: TCS-Low Price (Daily) | B49: Market Data | C49: 4,495.90 | D49: 2,132.80 | E49: 3,498.09 | F49: -1,632.60 | -43.36%
A50: TCS-Day Open Price (Daily) | B50: Market Data | C50: 4,576.00 | D50: 2,151.30 | E50: 3,547.57 | F50: -1,638.70 | -43.24%
A51: TCS-Volume (Daily) | B51: Market Data | C51: 16.33M | D51: 276.00 | E51: 2.85M | F51: -825,631.00 | -99.97%
A54: Pricing Date | B54: TCS-Share Price (Daily)(%) | C54: TCS-Volume (Daily) | D54: S&P Asia Pacific Emerging BMI Information Technology (Sector) Index-Index Value (Daily)(%) | E54: TCS-High Price (Daily)(%) | F54: TCS-Low Price (Daily)(%) | G54: TCS-Day Open Price (Daily)(%)
A55: 46184.249 | B55: NA | C55: 276 | D55: NA | E55: NA | F55: NA | G55: NA
A56: 46183 | B56: -43.483509 | C56: 2848650 | D56: 159.3734 | E56: -43.08977 | F56: -43.357943 | G56: -43.237467
A57: 46182 | B57: -43.559602 | C57: 4148655 | D57: 169.50775 | E57: -43.188935 | F57: -43.357943 | G57: -42.638522
A58: 46181 | B58: -43.549107 | C58: 6536734 | D58: 162.66944 | E58: -40.715031 | F58: -43.079089 | G58: -42.744063
A59: 46178 | B59: -42.302747 | C59: 5019717 | D59: 172.89737 | E59: -40.715031 | F59: -41.785733 | G59: -40.292876
A60: 46177 | B60: -41.198079 | C60: 4867263 | D60: 178.04919 | E60: -37.552192 | F60: -41.132416 | G60: -40.852243
A61: 46176 | B61: -41.179712 | C61: 15660060 | D61: 183.63557 | E61: -35.871608 | F61: -40.914644 | G61: -36.860158
A62: 46175 | B62: -35.79544 | C62: 11306120 | D62: 179.3051 | E62: -35.871608 | F62: -39.448664 | G62: -38.78628
A63: 46174 | B63: -39.718192 | C63: 7505095 | D63: 178.0294 | E63: -39.065762 | F63: -40.643756 | G63: -39.736148
A64: 46171 | B64: -40.728399 | C64: 16331580 | D64: 176.10741 | E64: -39.091858 | F64: -40.643756 | G64: -39.551451
A65: 46170 | B65: NA | C65: NA | D65: 170.04038 | E65: NA | F65: NA | G65: NA
A66: 46169 | B66: -40.064548 | C66: 2653950 | D66: 173.09471 | E66: -39.251044 | F66: -39.955914 | G66: -39.973615
A67: 46168 | B67: -40.274461 | C67: 3587597 | D67: 168.74369 | E67: -39.251044 | F67: -39.650502 | G67: -39.097625
A68: 46167 | B68: -39.434809 | C68: 3298364 | D68: 168.90703 | E68: -38.935282 | F68: -39.103415 | G68: -38.654354
A69: 46164 | B69: -39.196033 | C69: 2617262 | D69: 159.8275 | E69: -38.935282 | F69: -38.702395 | G69: -38.493404
A70: 46163 | B70: -38.936265 | C70: 3299087 | D70: 152.33071 | E70: -38.88309 | F70: -38.545706 | G70: -38.496042
A71: 46162 | B71: -38.931017 | C71: 2537422 | D71: 145.16222 | E71: -37.954071 | F71: -38.994529 | G71: -38.683377
A72: 46161 | B72: -38.938889 | C72: 10394700 | D72: 145.85272 | E72: -37.954071 | F72: -40.186966 | G72: -39.313984
A73: 46160 | B73: -40.090787 | C73: 3773336 | D73: 150.85952 | E73: -39.851253 | F73: -40.192277 | G73: -40.263852
A74: 46157 | B74: -40.594579 | C74: 3410637 | D74: 152.00367 | E74: -39.851253 | F74: -41.403304 | G74: -40.580475
A75: 46156 | B75: -41.066884 | C75: 5633313 | D75: 156.65484 | E75: -39.73904 | F75: -41.403304 | G75: -40.237467
A76: 46155 | B76: -40.363675 | C76: 3171843 | D76: 154.33937 | E76: -38.021921 | F76: -39.740798 | G76: -39.155673
A77: 46154 | B77: -39.642098 | C77: 6347884 | D77: 156.62286 | E77: -36.978079 | F77: -39.368991 | G77: -37.335092
... A83: 46146 | B83: -36.20477 | C83: 2632358 | D83: 146.71766 | E83: -34.80428 | F83: -35.597812 | G83: -34.195251
A84: 46143 | B84: NA | C84: NA | D84: 134.63938 | E84: NA | F84: NA | G84: NA
A85: 46142 | B85: -35.086983 | C85: 3970446 | D85: 134.58246 | E85: -34.994781 | F85: -35.252563 | G85: -34.591029
A86: 46141 | B86: -35.065991 | C86: 2835961 | D86: 137.14934 | E86: -35.075678 | F86: -35.534073 | G86: -35.329815
A87: 46140 | B87: -35.853166 | C87: 4508363 | D87: 139.05782 | E87: -35.099165 | F87: -36.34408 | G87: -35.514512
...

Sheet Bharti Airtel
A2: Bharti Airtel Limited | Stock Chart
A4: BSE:532454 (MI Key: 4200501; SPCIQ Key: 135466)
A7: Entities: Airtel, S&P Asia Pacific Emerging BMI Telecommunication Services (Industry Group) Index
A8: Metrics: Share Price, Volume
A45: SERIES NAME | B45: CATEGORY | C45: HIGH | D45: LOW | E45: AVERAGE | F45: CHANGE
A46: 532454-Share Price (Daily) | B46: Market Data | C46: 16.48 | D46: -5.39 | E46: 4.99 | F46: -4.38
A47: 532454-Volume (Daily) | B47: Market Data | C47: 13.42M | D47: 1,296.00 | E47: 405,359.99 | F47: -53,352.00 | -97.63%
A48: S&P Asia Pacific Emerging BMI Telecommunication Services (Industry Group) Index-Index Value (Daily) | B48: Market Data | C48: 5.77 | D48: -6.22 | E48: 0.39 | F48: -5.25
A51: Pricing Date | B51: 532454-Share Price (Daily)(%) | C51: 532454-Volume (Daily) | D51: S&P Asia Pacific Emerging BMI Telecommunication Services (Industry Group) Index-Index Value (Daily)(%)
A52: 46184.249 | B52: NA | C52: 1296 | D52: NA
A53: 46183 | B53: -4.3838863 | C53: 142572 | D53: -5.2486715
A54: 46182 | B54: -3.1721241 | C54: 428960 | D54: -5.0486528
A55: 46181 | B55: -2.2107928 | C55: 311330 | D55: -5.7745796
A56: 46178 | B56: -3.1155752 | C56: 130387 | D56: -3.9933697
A57: 46177 | B57: -2.0707669 | C57: 345473 | D57: -3.5017181
A58: 46176 | B58: -1.7476303 | C58: 145643 | D58: -3.1746512
A59: 46175 | B59: -2.3104265 | C59: 274109 | D59: -2.816425
A60: 46174 | B60: -2.4935373 | C60: 169501 | D60: -3.1738959
A61: 46171 | B61: -1.4595002 | C61: 2466778 | D61: -3.1537615
A62: 46170 | B62: NA | C62: NA | D62: -3.330185
A63: 46169 | B63: -0.29890134 | C63: 718758 | D63: -3.2353859
A64: 46168 | B64: -0.54663938 | C64: 139336 | D64: -3.2975939
A65: 46167 | B65: 0.98287376 | C65: 137104 | D65: -2.3428764
A66: 46164 | B66: 0.78629901 | C66: 169332 | D66: -3.0066147
A67: 46163 | B67: 1.5322059 | C67: 828322 | D67: -2.7423437
A68: 46162 | B68: 2.6120207 | C68: 456826 | D68: -1.8686912
A69: 46161 | B69: 3.0590263 | C69: 242651 | D69: -0.778631
A70: 46160 | B70: 4.3785006 | C70: 668590 | D70: -0.81568259
A71: 46157 | B71: 2.5743214 | C71: 1340152 | D71: -0.95218048
A72: 46156 | B72: 1.4244938 | C72: 1608902 | D72: -1.1461891
A73: 46155 | B73: -3.6999138 | C73: 457675 | D73: -3.6062366
A74: 46154 | B74: -5.3883025 | C74: 898058 | D74: -4.9375039
... A80: 46146 | B80: -1.6102973 | C80: 230203 | D80: -4.3776086
A81: 46143 | B81: NA | C81: NA | D81: -3.466724
A82: 46142 | B82: 1.5752908 | C82: 752989 | D82: -3.4669706
A83: 46141 | B83: 1.6776174 | C83: 315273 | D83: -2.9141606
A84: 46140 | B84: -0.6112667 | C84: 205630 | D84: -3.5804629
A85: 46139 | B85: -2.0088324 | C85: 156992 | D85: -3.9261258
A86: 46136 | B86: -2.2673417 | C86: 272214 | D86: -4.492474
A87: 46135 | B87: -0.86977596 | C87: 618255 | D87: -3.6901545
...

Sheet Wipro
A2: Wipro Limited | Stock Chart
A4: BSE:507685 (MI Key: 4223478; SPCIQ Key: 598611)
A7: Entities: Wipro Ltd., S&P Asia Pacific Emerging BMI Information Technology (Sector) Index
A8: Metrics: Share Price, Volume
A45: SERIES NAME | B45: CATEGORY | C45: HIGH | D45: LOW | E45: AVERAGE | F45: CHANGE
A46: 507685-Share Price (Daily) | B46: Market Data | C46: 6.93 | D46: -30.33 | E46: -7.90 | F46: -30.33
A47: 507685-Volume (Daily) | B47: Market Data | C47: 6.52M | D47: 7,272.00 | E47: 668,303.02 | F47: -533,539.00 | -98.66%
A48: S&P Asia Pacific Emerging BMI Information Technology (Sector) Index-Index Value (Daily) | B48: Market Data | C48: 108.01 | D48: -1.27 | E48: 34.68 | F48: 90.21
A51: Pricing Date | B51: 507685-Share Price (Daily)(%) | C51: 507685-Volume (Daily) | D51: S&P Asia Pacific Emerging BMI Information Technology (Sector) Index-Index Value (Daily)(%)
A52: 46184.249 | B52: -30.331568 | C52: 7272 | D52: NA
A53: 46183 | B53: -29.782225 | C53: 1342771 | D53: 90.214637
A54: 46182 | B54: -28.683539 | C54: 1479015 | D54: 97.646785
A55: 46181 | B55: -28.66392 | C55: 2530772 | D55: 92.631829
A56: 46178 | B56: -22.169904 | C56: 2181920 | D56: 100.13261
A57: 46177 | B57: -19.835197 | C57: 2647042 | D57: 103.91076
A58: 46176 | B58: -19.894055 | C58: 3171366 | D58: 108.0076
A59: 46175 | B59: -17.657446 | C59: 3036846 | D59: 104.83179
A60: 46174 | B60: -18.991564 | C60: 1171756 | D60: 103.89624
A61: 46171 | B61: -19.874436 | C61: 3960387 | D61: 102.48673
A62: 46170 | B62: NA | C62: NA | D62: 98.037396
A63: 46169 | B63: -20.894644 | C63: 2039590 | D63: 100.27733
A64: 46168 | B64: -20.011772 | C64: 977531 | D64: 97.086458
A65: 46167 | B65: -18.854228 | C65: 2528080 | D65: 97.206244
A66: 46164 | B66: -20.306062 | C66: 2637969 | D66: 90.547655
A67: 46163 | B67: -21.600942 | C67: 1585078 | D67: 85.049798
A68: 46162 | B68: -22.640769 | C68: 586772 | D68: 79.7927
A69: 46161 | B69: -23.425544 | C69: 1419743 | D69: 80.29908
A70: 46160 | B70: -24.583088 | C70: 564017 | D70: 83.970882
A71: 46157 | B71: -25.46596 | C71: 904061 | D71: 84.809954
A72: 46156 | B72: -26.074161 | C72: 990161 | D72: 88.22095
A73: 46155 | B73: -26.309594 | C73: 691961 | D73: 86.522873
A74: 46154 | B74: -25.622915 | C74: 953791 | D74: 88.197495
... A80: 46146 | B80: -21.208554 | C80: 455934 | D80: 80.9334
A81: 46143 | B81: NA | C81: NA | D81: 72.075644
A82: 46142 | B82: -21.267412 | C82: 937945 | D82: 72.033902
A83: 46141 | B83: -21.247793 | C83: 775163 | D83: 73.916354
A84: 46140 | B84: -20.875025 | C84: 841410 | D84: 75.315964
A85: 46139 | B85: -19.540906 | C85: 1876136 | D85: 77.190408
A86: 46136 | B86: -21.757897 | C86: 1685125 | D86: 73.020426
A87: 46135 | B87: -20.364921 | C87: 1081046 | D87: 67.516828
...

Sheet Adani Enterprises
A2: Adani Enterprises Limited | Stock Chart
A4: BSE:512599 (MI Key: 4347779; SPCIQ Key: 883013)
A7: Entities: Adani Enterprises Ltd., S&P Asia Pacific Emerging BMI Capital Goods (Industry Group) Index
A8: Metrics: Share Price, Volume
A45: SERIES NAME | B45: CATEGORY | C45: HIGH | D45: LOW | E45: AVERAGE | F45: CHANGE
A46: 512599-Share Price (Daily) | B46: Market Data | C46: 16.61 | D46: -32.68 | E46: -9.52 | F46: 11.51
A47: 512599-Volume (Daily) | B47: Market Data | C47: 5.73M | D47: 106.00 | E47: 127,212.03 | F47: -59,022.00 | -99.82%
A48: S&P Asia Pacific Emerging BMI Capital Goods (Industry Group) Index-Index Value (Daily) | B48: Market Data | C48: 25.23 | D48: -2.49 | E48: 10.68 | F48: 15.85
A51: Pricing Date | B51: 512599-Share Price (Daily)(%) | C51: 512599-Volume (Daily) | D51: S&P Asia Pacific Emerging BMI Capital Goods (Industry Group) Index-Index Value (Daily)(%)
A52: 46184.249 | B52: 11.512415 | C52: 106 | D52: NA
A53: 46183 | B53: 12.103531 | C53: 79435 | D53: 15.852167
A54: 46182 | B54: 13.94766 | C54: 109280 | D54: 18.653258
A55: 46181 | B55: 13.706623 | C55: 97359 | D55: 16.703036
A56: 46178 | B56: 16.610552 | C56: 2539242 | D56: 20.205718
A57: 46177 | B57: 13.739144 | C57: 71826 | D57: 21.031939
A58: 46176 | B58: 11.917971 | C58: 67685 | D58: 21.358716
A59: 46175 | B59: 13.553583 | C59: 91361 | D59: 20.888438
A60: 46174 | B60: 11.294334 | C60: 126010 | D60: 20.854945
A61: 46171 | B61: 12.470827 | C61: 99958 | D61: 21.8646
A62: 46170 | B62: NA | C62: NA | D62: 22.302731
A63: 46169 | B63: 13.731492 | C63: 301201 | D63: 22.860569
A64: 46168 | B64: 13.607147 | C64: 267660 | D64: 22.492278
A65: 46167 | B65: 9.0140414 | C65: 290535 | D65: 23.045076
A66: 46164 | B66: 3.9905115 | C66: 62970 | D66: 21.360394
A67: 46163 | B67: 3.1354019 | C67: 149903 | D67: 19.588028
A68: 46162 | B68: 3.4931323 | C68: 72553 | D68: 19.093557
A69: 46161 | B69: 4.1378123 | C69: 316949 | D69: 19.102163
A70: 46160 | B70: 2.9307113 | C70: 127900 | D70: 19.389106
A71: 46157 | B71: 3.9101657 | C71: 526211 | D71: 20.473041
A72: 46156 | B72: 3.8202548 | C72: 1055463 | D72: 21.915032
A73: 46155 | B73: -4.3558939 | C73: 79436 | D73: 22.977276
A74: 46154 | B74: -7.99824 | C74: 91740 | D74: 22.150133
... A80: 46146 | B80: -4.9795309 | C80: 220708 | D80: 21.909332
A81: 46143 | B81: NA | C81: NA | D81: 20.272747
A82: 46142 | B82: -8.021196 | C82: 361770 | D82: 20.241347
A83: 46141 | B83: -7.2311283 | C83: 222027 | D83: 20.868464
A84: 46140 | B84: -7.7610284 | C84: 217193 | D84: 19.843969
A85: 46139 | B85: -11.185293 | C85: 105376 | D85: 20.387483
A86: 46136 | B86: -12.512913 | C86: 185872 | D86: 20.245985
A87: 46135 | B87: -11.983013 | C87: 263051 | D87: 20.911207
...

Sheet Godrej
A2: Godrej Industries Limited | Stock Chart
A4: BSE:500164 (MI Key: 6333262; SPCIQ Key: 874188)
A7: Entities: Godrej Industries Ltd., S&P Asia Pacific Emerging BMI Capital Goods (Industry Group) Index
A8: Metrics: Share Price, Volume
A45: SERIES NAME | B45: CATEGORY | C45: HIGH | D45: LOW | E45: AVERAGE | F45: CHANGE
A46: 500164-Share Price (Daily) | B46: Market Data | C46: 2.03 | D46: -43.39 | E46: -18.98 | F46: -23.88
A47: 500164-Volume (Daily) | B47: Market Data | C47: 11.22M | D47: 343.00 | E47: 56,327.89 | F47: -4,499.00 | -92.92%
A48: S&P Asia Pacific Emerging BMI Capital Goods (Industry Group) Index-Index Value (Daily) | B48: Market Data | C48: 25.23 | D48: -2.49 | E48: 10.68 | F48: 15.85
A51: Pricing Date | B51: 500164-Share Price (Daily)(%) | C51: 500164-Volume (Daily) | D51: S&P Asia Pacific Emerging BMI Capital Goods (Industry Group) Index-Index Value (Daily)(%)
A52: 46184.249 | B52: -23.880145 | C52: 343 | D52: NA
A53: 46183 | B53: -21.526937 | C53: 8799 | D53: 15.852167
A54: 46182 | B54: -20.963226 | C54: 13993 | D54: 18.653258
A55: 46181 | B55: -21.795551 | C55: 3908 | D55: 16.703036
A56: 46178 | B56: -21.118341 | C56: 3657 | D56: 20.205718
A57: 46177 | B57: -20.747579 | C57: 9370 | D57: 21.031939
A58: 46176 | B58: -20.130902 | C58: 6022 | D58: 21.358716
A59: 46175 | B59: -19.881205 | C59: 7948 | D59: 20.888438
A60: 46174 | B60: -17.433414 | C60: 16919 | D60: 20.854945
A61: 46171 | B61: -16.120611 | C61: 18532 | D61: 21.8646
A62: 46170 | B62: NA | C62: NA | D62: 22.302731
A63: 46169 | B63: -14.251665 | C63: 6893 | D63: 22.860569
A64: 46168 | B64: -13.532839 | C64: 5624 | D64: 22.492278
A65: 46167 | B65: -12.307052 | C65: 7161 | D65: 23.045076
A66: 46164 | B66: -14.777542 | C66: 4902 | D66: 21.360394
A67: 46163 | B67: -15.984413 | C67: 7394 | D67: 19.588028
A68: 46162 | B68: -14.826725 | C68: 8770 | D68: 19.093557
A69: 46161 | B69: -13.998184 | C69: 13250 | D69: 19.102163
A70: 46160 | B70: -12.360018 | C70: 44149 | D70: 19.389106
A71: 46157 | B71: -14.342464 | C71: 18817 | D71: 20.473041
A72: 46156 | B72: -12.83293 | C72: 265767 | D72: 21.915032
A73: 46155 | B73: -18.878632 | C73: 6848 | D73: 22.977276
A74: 46154 | B74: -17.792827 | C74: 22949 | D74: 22.150133
... A80: 46146 | B80: -26.90678 | C80: 7535 | D80: 21.909332
A81: 46143 | B81: NA | C81: NA | D81: 20.272747
A82: 46142 | B82: -27.531023 | C82: 5130 | D82: 20.241347
A83: 46141 | B83: -27.372125 | C83: 12518 | D83: 20.868464
A84: 46140 | B84: -25.105932 | C84: 11161 | D84: 19.843969
A85: 46139 | B85: -24.636804 | C85: 9338 | D85: 20.387483
A86: 46136 | B86: -24.912984 | C86: 31434 | D86: 20.245985
A87: 46135 | B87: -24.65572 | C87: 167189 | D87: 20.911207
...

Sheet Covariance & Correlation
A1: Variance-Covariance Matrix (Daily Log Returns)
B3: TCS | C3: Wipro | D3: Bharti Airtel | E3: Adani Ent | F3: Godrej Ind
A4: TCS | B4: =SUMPRODUCT(('Historical VaR'!I19:I262-AVERAGE('Historical VaR'!I19:I262))*('Historical VaR'!I19:I262-AVERAGE('Historical VaR'!I19:I262)))/(COUNT('Historical VaR'!I19:I262)-1) -> 0.00024427563 | C4: =SUMPRODUCT(('Historical VaR'!I19:I262-AVERAGE('Historical VaR'!I19:I262))*('Historical VaR'!J19:J262-AVERAGE('Historical VaR'!J19:J262)))/(COUNT('Historical VaR'!I19:I262)-1) -> 0.00015500873 | D4: =SUMPRODUCT(('Historical VaR'!I19:I262-AVERAGE('Historical VaR'!I19:I262))*('Historical VaR'!K19:K262-AVERAGE('Historical VaR'!K19:K262)))/(COUNT('Historical VaR'!I19:I262)-1) -> 2.9063358e-05 | E4: =SUMPRODUCT(('Historical VaR'!I19:I262-AVERAGE('Historical VaR'!I19:I262))*('Historical VaR'!L19:L262-AVERAGE('Historical VaR'!L19:L262)))/(COUNT('Historical VaR'!I19:I262)-1) -> 5.298052e-05 | F4: =SUMPRODUCT(('Historical VaR'!I19:I262-AVERAGE('Historical VaR'!I19:I262))*('Historical VaR'!M19:M262-AVERAGE('Historical VaR'!M19:M262)))/(COUNT('Historical VaR'!I19:I262)-1) -> 2.1738813e-05
A5: Wipro | B5: =SUMPRODUCT(('Historical VaR'!J19:J262-AVERAGE('Historical VaR'!J19:J262))*('Historical VaR'!I19:I262-AVERAGE('Historical VaR'!I19:I262)))/(COUNT('Historical VaR'!J19:J262)-1) -> 0.00015500873 | C5: =SUMPRODUCT(('Historical VaR'!J19:J262-AVERAGE('Historical VaR'!J19:J262))*('Historical VaR'!J19:J262-AVERAGE('Historical VaR'!J19:J262)))/(COUNT('Historical VaR'!J19:J262)-1) -> 0.00025804339 | D5: =SUMPRODUCT(('Historical VaR'!J19:J262-AVERAGE('Historical VaR'!J19:J262))*('Historical VaR'!K19:K262-AVERAGE('Historical VaR'!K19:K262)))/(COUNT('Historical VaR'!J19:J262)-1) -> 2.0543854e-05 | E5: =SUMPRODUCT(('Historical VaR'!J19:J262-AVERAGE('Historical VaR'!J19:J262))*('Historical VaR'!L19:L262-AVERAGE('Historical VaR'!L19:L262)))/(COUNT('Historical VaR'!J19:J262)-1) -> 6.5195126e-05 | F5: =SUMPRODUCT(('Historical VaR'!J19:J262-AVERAGE('Historical VaR'!J19:J262))*('Historical VaR'!M19:M262-AVERAGE('Historical VaR'!M19:M262)))/(COUNT('Historical VaR'!J19:J262)-1) -> 6.7447632e-05
A6: Bharti Airtel | B6: =SUMPRODUCT(('Historical VaR'!K19:K262-AVERAGE('Historical VaR'!K19:K262))*('Historical VaR'!I19:I262-AVERAGE('Historical VaR'!I19:I262)))/(COUNT('Historical VaR'!K19:K262)-1) -> 2.9063358e-05 | C6: =SUMPRODUCT(('Historical VaR'!K19:K262-AVERAGE('Historical VaR'!K19:K262))*('Historical VaR'!J19:J262-AVERAGE('Historical VaR'!J19:J262)))/(COUNT('Historical VaR'!K19:K262)-1) -> 2.0543854e-05 | D6: =SUMPRODUCT(('Historical VaR'!K19:K262-AVERAGE('Historical VaR'!K19:K262))*('Historical VaR'!K19:K262-AVERAGE('Historical VaR'!K19:K262)))/(COUNT('Historical VaR'!K19:K262)-1) -> 0.00015401237 | E6: =SUMPRODUCT(('Historical VaR'!K19:K262-AVERAGE('Historical VaR'!K19:K262))*('Historical VaR'!L19:L262-AVERAGE('Historical VaR'!L19:L262)))/(COUNT('Historical VaR'!K19:K262)-1) -> 8.2536483e-05 | F6: =SUMPRODUCT(('Historical VaR'!K19:K262-AVERAGE('Historical VaR'!K19:K262))*('Historical VaR'!M19:M262-AVERAGE('Historical VaR'!M19:M262)))/(COUNT('Historical VaR'!K19:K262)-1) -> 4.8098191e-05
A7: Adani Ent | B7: =SUMPRODUCT(('Historical VaR'!L19:L262-AVERAGE('Historical VaR'!L19:L262))*('Historical VaR'!I19:I262-AVERAGE('Historical VaR'!I19:I262)))/(COUNT('Historical VaR'!L19:L262)-1) -> 5.298052e-05 | C7: =SUMPRODUCT(('Historical VaR'!L19:L262-AVERAGE('Historical VaR'!L19:L262))*('Historical VaR'!J19:J262-AVERAGE('Historical VaR'!J19:J262)))/(COUNT('Historical VaR'!L19:L262)-1) -> 6.5195126e-05 | D7: =SUMPRODUCT(('Historical VaR'!L19:L262-AVERAGE('Historical VaR'!L19:L262))*('Historical VaR'!K19:K262-AVERAGE('Historical VaR'!K19:K262)))/(COUNT('Historical VaR'!L19:L262)-1) -> 8.2536483e-05 | E7: =SUMPRODUCT(('Historical VaR'!L19:L262-AVERAGE('Historical VaR'!L19:L262))*('Historical VaR'!L19:L262-AVERAGE('Historical VaR'!L19:L262)))/(COUNT('Historical VaR'!L19:L262)-1) -> 0.00047837158 | F7: =SUMPRODUCT(('Historical VaR'!L19:L262-AVERAGE('Historical VaR'!L19:L262))*('Historical VaR'!M19:M262-AVERAGE('Historical VaR'!M19:M262)))/(COUNT('Historical VaR'!L19:L262)-1) -> 0.00014842479
A8: Godrej Ind | B8: =SUMPRODUCT(('Historical VaR'!M19:M262-AVERAGE('Historical VaR'!M19:M262))*('Historical VaR'!I19:I262-AVERAGE('Historical VaR'!I19:I262)))/(COUNT('Historical VaR'!M19:M262)-1) -> 2.1738813e-05 | C8: =SUMPRODUCT(('Historical VaR'!M19:M262-AVERAGE('Historical VaR'!M19:M262))*('Historical VaR'!J19:J262-AVERAGE('Historical VaR'!J19:J262)))/(COUNT('Historical VaR'!M19:M262)-1) -> 6.7447632e-05 | D8: =SUMPRODUCT(('Historical VaR'!M19:M262-AVERAGE('Historical VaR'!M19:M262))*('Historical VaR'!K19:K262-AVERAGE('Historical VaR'!K19:K262)))/(COUNT('Historical VaR'!M19:M262)-1) -> 4.8098191e-05 | E8: =SUMPRODUCT(('Historical VaR'!M19:M262-AVERAGE('Historical VaR'!M19:M262))*('Historical VaR'!L19:L262-AVERAGE('Historical VaR'!L19:L262)))/(COUNT('Historical VaR'!M19:M262)-1) -> 0.00014842479 | F8: =SUMPRODUCT(('Historical VaR'!M19:M262-AVERAGE('Historical VaR'!M19:M262))*('Historical VaR'!M19:M262-AVERAGE('Historical VaR'!M19:M262)))/(COUNT('Historical VaR'!M19:M262)-1) -> 0.00057206626
A11: Correlation Matrix
B13: TCS | C13: Wipro | D13: Bharti Airtel | E13: Adani Ent | F13: Godrej Ind
A14: TCS | B14: =CORREL('Historical VaR'!I19:I262,'Historical VaR'!I19:I262) -> 1 | C14: =CORREL('Historical VaR'!I19:I262,'Historical VaR'!J19:J262) -> 0.6174044 | D14: =CORREL('Historical VaR'!I19:I262,'Historical VaR'!K19:K262) -> 0.14984005 | E14: =CORREL('Historical VaR'!I19:I262,'Historical VaR'!L19:L262) -> 0.15498635 | F14: =CORREL('Historical VaR'!I19:I262,'Historical VaR'!M19:M262) -> 0.058153062
A15: Wipro | B15: =CORREL('Historical VaR'!J19:J262,'Historical VaR'!I19:I262) -> 0.6174044 | C15: =CORREL('Historical VaR'!J19:J262,'Historical VaR'!J19:J262) -> 1 | D15: =CORREL('Historical VaR'!J19:J262,'Historical VaR'!K19:K262) -> 0.10305231 | E15: =CORREL('Historical VaR'!J19:J262,'Historical VaR'!L19:L262) -> 0.18556073 | F15: =CORREL('Historical VaR'!J19:J262,'Historical VaR'!M19:M262) -> 0.17554852
A16: Bharti Airtel | B16: =CORREL('Historical VaR'!K19:K262,'Historical VaR'!I19:I262) -> 0.14984005 | C16: =CORREL('Historical VaR'!K19:K262,'Historical VaR'!J19:J262) -> 0.10305231 | D16: =CORREL('Historical VaR'!K19:K262,'Historical VaR'!K19:K262) -> 1 | E16: =CORREL('Historical VaR'!K19:K262,'Historical VaR'!L19:L262) -> 0.30407832 | F16: =CORREL('Historical VaR'!K19:K262,'Historical VaR'!M19:M262) -> 0.16204207
A17: Adani Ent | B17: =CORREL('Historical VaR'!L19:L262,'Historical VaR'!I19:I262) -> 0.15498635 | C17: =CORREL('Historical VaR'!L19:L262,'Historical VaR'!J19:J262) -> 0.18556073 | D17: =CORREL('Historical VaR'!L19:L262,'Historical VaR'!K19:K262) -> 0.30407832 | E17: =CORREL('Historical VaR'!L19:L262,'Historical VaR'!L19:L262) -> 1 | F17: =CORREL('Historical VaR'!L19:L262,'Historical VaR'!M19:M262) -> 0.28372694
A18: Godrej Ind | B18: =CORREL('Historical VaR'!M19:M262,'Historical VaR'!I19:I262) -> 0.058153062 | C18: =CORREL('Historical VaR'!M19:M262,'Historical VaR'!J19:J262) -> 0.17554852 | D18: =CORREL('Historical VaR'!M19:M262,'Historical VaR'!K19:K262) -> 0.16204207 | E18: =CORREL('Historical VaR'!M19:M262,'Historical VaR'!L19:L262) -> 0.28372694 | F18: =CORREL('Historical VaR'!M19:M262,'Historical VaR'!M19:M262) -> 1
A21: Individual Stock Risk Statistics (Daily)
A23: Stock | B23: Mean Return | C23: Std Dev | D23: Variance | E23: Annualized Vol
A24: TCS | B24: =AVERAGE('Historical VaR'!I19:I262) -> -0.0019256021 | C24: =STDEV('Historical VaR'!I19:I262) -> 0.01562932 | D24: =VAR('Historical VaR'!I19:I262) -> 0.00024427563 | E24: =C24*SQRT(252) -> 0.24810776
A25: Wipro | B25: =AVERAGE('Historical VaR'!J19:J262) -> -0.0015341972 | C25: =STDEV('Historical VaR'!J19:J262) -> 0.016063729 | D25: =VAR('Historical VaR'!J19:J262) -> 0.00025804339 | E25: =C25*SQRT(252) -> 0.25500379
A26: Bharti Airtel | B26: =AVERAGE('Historical VaR'!K19:K262) -> -0.00015126073 | C26: =STDEV('Historical VaR'!K19:K262) -> 0.012410172 | D26: =VAR('Historical VaR'!K19:K262) -> 0.00015401237 | E26: =C26*SQRT(252) -> 0.19700538
A27: Adani Ent | B27: =AVERAGE('Historical VaR'!L19:L262) -> 0.00063964052 | C27: =STDEV('Historical VaR'!L19:L262) -> 0.021871707 | D27: =VAR('Historical VaR'!L19:L262) -> 0.00047837158 | E27: =C27*SQRT(252) -> 0.34720259
A28: Godrej Ind | B28: =AVERAGE('Historical VaR'!M19:M262) -> -0.00085954241 | C28: =STDEV('Historical VaR'!M19:M262) -> 0.023917907 | D28: =VAR('Historical VaR'!M19:M262) -> 0.00057206626 | E28: =C28*SQRT(252) -> 0.379685

Sheet Parametric VaR
A1: Variance-Covariance (Parametric) VaR Calculation
A2: VaR = z * σ_portfolio * Portfolio Value, where σ_portfolio = sqrt(w' * Σ * w)
A4: Step 1: Portfolio Weights
B5: TCS | C5: Wipro | D5: Bharti Airtel | E5: Adani Ent | F5: Godrej Ind
A6: Weight (w) | B6: ='Historical VaR'!D7 -> 0.2 | C6: ='Historical VaR'!D8 -> 0.2 | D6: ='Historical VaR'!D9 -> 0.2 | E6: ='Historical VaR'!D10 -> 0.2 | F6: ='Historical VaR'!D11 -> 0.2
A7: Amount (INR) | B7: ='Historical VaR'!C7 -> 100000 | C7: ='Historical VaR'!C8 -> 100000 | D7: ='Historical VaR'!C9 -> 100000 | E7: ='Historical VaR'!C10 -> 100000 | F7: ='Historical VaR'!C11 -> 100000
A8: Total Portfolio | B8: ='Historical VaR'!C12 -> 500000
A10: Step 2: Covariance Matrix (Σ) - Referenced from Covariance & Correlation sheet
B11: TCS | C11: Wipro | D11: Bharti Airtel | E11: Adani Ent | F11: Godrej Ind
A12: TCS | B12: ='Covariance & Correlation'!B4 -> 0.00024427563 | C12: ='Covariance & Correlation'!C4 -> 0.00015500873 | D12: ='Covariance & Correlation'!D4 -> 2.9063358e-05 | E12: ='Covariance & Correlation'!E4 -> 5.298052e-05 | F12: ='Covariance & Correlation'!F4 -> 2.1738813e-05
A13: Wipro | B13: ='Covariance & Correlation'!B5 -> 0.00015500873 | C13: ='Covariance & Correlation'!C5 -> 0.00025804339 | D13: ='Covariance & Correlation'!D5 -> 2.0543854e-05 | E13: ='Covariance & Correlation'!E5 -> 6.5195126e-05 | F13: ='Covariance & Correlation'!F5 -> 6.7447632e-05
A14: Bharti Airtel | B14: ='Covariance & Correlation'!B6 -> 2.9063358e-05 | C14: ='Covariance & Correlation'!C6 -> 2.0543854e-05 | D14: ='Covariance & Correlation'!D6 -> 0.00015401237 | E14: ='Covariance & Correlation'!E6 -> 8.2536483e-05 | F14: ='Covariance & Correlation'!F6 -> 4.8098191e-05
A15: Adani Ent | B15: ='Covariance & Correlation'!B7 -> 5.298052e-05 | C15: ='Covariance & Correlation'!C7 -> 6.5195126e-05 | D15: ='Covariance & Correlation'!D7 -> 8.2536483e-05 | E15: ='Covariance & Correlation'!E7 -> 0.00047837158 | F15: ='Covariance & Correlation'!F7 -> 0.00014842479
A16: Godrej Ind | B16: ='Covariance & Correlation'!B8 -> 2.1738813e-05 | C16: ='Covariance & Correlation'!C8 -> 6.7447632e-05 | D16: ='Covariance & Correlation'!D8 -> 4.8098191e-05 | E16: ='Covariance & Correlation'!E8 -> 0.00014842479 | F16: ='Covariance & Correlation'!F8 -> 0.00057206626
A19: Step 3: Weighted Covariance Matrix (w_i × w_j × σ_ij)
A20: Each cell = Weight_i × Weight_j × Covariance(i,j)
B21: TCS | C21: Wipro | D21: Bharti Airtel | E21: Adani Ent | F21: Godrej Ind
A22: TCS | B22: =$B$6*$B$6*B12 -> 9.7710252e-06 | C22: =$B$6*$C$6*C12 -> 6.2003492e-06 | D22: =$B$6*$D$6*D12 -> 1.1625343e-06 | E22: =$B$6*$E$6*E12 -> 2.1192208e-06 | F22: =$B$6*$F$6*F12 -> 8.6955252e-07
A23: Wipro | B23: =$C$6*$B$6*B13 -> 6.2003492e-06 | C23: =$C$6*$C$6*C13 -> 1.0321736e-05 | D23: =$C$6*$D$6*D13 -> 8.2175417e-07 | E23: =$C$6*$E$6*E13 -> 2.607805e-06 | F23: =$C$6*$F$6*F13 -> 2.6979053e-06
A24: Bharti Airtel | B24: =$D$6*$B$6*B14 -> 1.1625343e-06 | C24: =$D$6*$C$6*C14 -> 8.2175417e-07 | D24: =$D$6*$D$6*D14 -> 6.160495e-06 | E24: =$D$6*$E$6*E14 -> 3.3014593e-06 | F24: =$D$6*$F$6*F14 -> 1.9239276e-06
A25: Adani Ent | B25: =$E$6*$B$6*B15 -> 2.1192208e-06 | C25: =$E$6*$C$6*C15 -> 2.607805e-06 | D25: =$E$6*$D$6*D15 -> 3.3014593e-06 | E25: =$E$6*$E$6*E15 -> 1.9134863e-05 | F25: =$E$6*$F$6*F15 -> 5.9369914e-06
A26: Godrej Ind | B26: =$F$6*$B$6*B16 -> 8.6955252e-07 | C26: =$F$6*$C$6*C16 -> 2.6979053e-06 | D26: =$F$6*$D$6*D16 -> 1.9239276e-06 | E26: =$F$6*$E$6*E16 -> 5.9369914e-06 | F26: =$F$6*$F$6*F16 -> 2.288265e-05
A29: Step 4: Portfolio Variance & Standard Deviation
A31: Portfolio Variance (daily) | B31: =SUM(B22:F26) -> 0.00012355377
A32: Portfolio Std Dev (daily) | B32: =SQRT(B31) -> 0.011115474
A33: Annualized Std Dev (×√252) | B33: =B32*SQRT(252) -> 0.17645268
A35: Step 5: Parametric VaR Results
A36: VaR = z × σ_portfolio × Portfolio Value
A38: Metric | B38: z-score | C38: VaR (%) | D38: VaR (INR) | E38: VaR 10-day (INR)
A39: 95% Confidence (1-tail) | B39: 1.645 | C39: =B39*B32 -> 0.018284955 | D39: =C39*B8 -> 9142.4776 | E39: =D39*SQRT(10) -> 28911.053
A40: 99% Confidence (1-tail) | B40: 2.326 | C40: =B40*B32 -> 0.025854593 | D40: =C40*B8 -> 12927.297 | E40: =D40*SQRT(10) -> 40879.701
A42: Step 6: Comparison - Historical Simulation vs Parametric VaR
A44: Method | B44: 95% VaR (INR) | C44: 99% VaR (INR) | D44: 95% 10-day (INR) | E44: 99% 10-day (INR)
A45: Historical Simulation | B45: ='Historical VaR'!J8 -> 11683.91 | C45: ='Historical VaR'!J10 -> 14647.667 | D45: ='Historical VaR'!J11 -> 36947.769 | E45: ='Historical VaR'!J12 -> 46319.989
A46: Parametric (Var-Cov) | B46: =D39 -> 9142.4776 | C46: =D40 -> 12927.297 | D46: =E39 -> 28911.053 | E46: =E40 -> 40879.701
A47: Difference (HS - Parametric) | B47: =B45-B46 -> 2541.4327 | C47: =C45-C46 -> 1720.3702 | D47: =D45-D46 -> 8036.7159 | E47: =E45-E46 -> 5440.2881
A49: Interpretation:
A50: If Historical VaR > Parametric VaR, actual returns have fatter tails than the normal distribution assumes (leptokurtosis).
A51: Parametric VaR assumes returns are normally distributed. Historical Simulation makes no distributional assumption.
A52: The difference highlights the limitation of the normality assumption in the Parametric method.
